<mujoco model="mini_mec_six_arm">
  <compiler angle="radian" meshdir="./"/>

  <asset>
    <mesh name="base_link" file="base_link.STL"/>
    <mesh name="left_front_wheel_link" file="left_front_wheel_link.STL"/>
    <mesh name="left_rear_wheel_link" file="left_rear_wheel_link.STL"/>
    <mesh name="right_front_wheel_link" file="right_front_wheel_link.STL"/>
    <mesh name="right_rear_wheel_link" file="right_rear_wheel_link.STL"/>
    <mesh name="link1" file="link1.STL"/>
    <mesh name="link2" file="link2.STL"/>
    <mesh name="link3" file="link3.STL"/>
    <mesh name="link4" file="link4.STL"/>
    <mesh name="link5" file="link5.STL"/>
    <mesh name="link6" file="link6.STL"/>
    <mesh name="link7" file="link7.STL"/>
    <mesh name="link8" file="link8.STL"/>
    <mesh name="link9" file="link9.STL"/>
    <mesh name="link10" file="link10.STL"/>
    <mesh name="link11" file="link11.STL"/>
  </asset>

  <worldbody>
    <geom type="mesh" contype="0" conaffinity="0" group="1" density="0" rgba="1 1 1 1" mesh="base_link"/>
    <geom type="mesh" rgba="1 1 1 1" mesh="base_link"/>
    <body name="left_front_wheel_link" pos="0.094976 0.076703 0.038001">
      <inertial pos="-3.09795e-06 0.0173322 4.43766e-06" quat="0.607654 0.361378 0.361142 0.608062" mass="0.0503853" diaginertia="7.74121e-06 5.77324e-06 5.77168e-06"/>
      <joint name="left_front_wheel_joint" pos="0 0 0" axis="0 1 0"/>
      <geom type="mesh" contype="0" conaffinity="0" group="1" density="0" rgba="1 1 1 1" mesh="left_front_wheel_link"/>
      <geom type="mesh" rgba="1 1 1 1" mesh="left_front_wheel_link"/>
    </body>
    <body name="left_rear_wheel_link" pos="-0.078024 0.076703 0.038001">
      <inertial pos="-3.06188e-06 0.0173319 -5.84141e-06" quat="0.364611 0.605718 0.606127 0.364382" mass="0.0503852" diaginertia="7.74123e-06 5.7732e-06 5.77165e-06"/>
      <joint name="left_rear_wheel_joint" pos="0 0 0" axis="0 1 0"/>
      <geom type="mesh" contype="0" conaffinity="0" group="1" density="0" rgba="1 1 1 1" mesh="left_rear_wheel_link"/>
      <geom type="mesh" rgba="1 1 1 1" mesh="left_rear_wheel_link"/>
    </body>
    <body name="right_front_wheel_link" pos="0.094976 -0.075297 0.038001">
      <inertial pos="3.0624e-06 -0.0173319 -5.84118e-06" quat="0.60563 0.364757 0.364529 0.606039" mass="0.0503852" diaginertia="7.74123e-06 5.7732e-06 5.77165e-06"/>
      <joint name="right_front_wheel_joint" pos="0 0 0" axis="0 1 0"/>
      <geom type="mesh" contype="0" conaffinity="0" group="1" density="0" rgba="1 1 1 1" mesh="right_front_wheel_link"/>
      <geom type="mesh" rgba="1 1 1 1" mesh="right_front_wheel_link"/>
    </body>
    <body name="right_rear_wheel_link" pos="-0.078024 -0.075297 0.038001">
      <inertial pos="3.09795e-06 -0.0173322 4.43766e-06" quat="0.361378 0.607654 0.608062 0.361142" mass="0.0503853" diaginertia="7.74121e-06 5.77324e-06 5.77168e-06"/>
      <joint name="right_rear_wheel_joint" pos="0 0 0" axis="0 1 0"/>
      <geom type="mesh" contype="0" conaffinity="0" group="1" density="0" rgba="1 1 1 1" mesh="right_rear_wheel_link"/>
      <geom type="mesh" rgba="1 1 1 1" mesh="right_rear_wheel_link"/>
    </body>
    <body name="link1" pos="0.054476 0.00070272 0.156">
      <inertial pos="0.00667903 -0.000617925 0.0234455" quat="0.070451 0.703639 -0.0617965 0.70435" mass="0.0586503" diaginertia="2.71803e-05 1.53914e-05 1.45597e-05"/>
      <joint name="joint1" pos="0 0 0" axis="0 0 -1" range="-1.57 1.57"/>
      <geom type="mesh" contype="0" conaffinity="0" group="1" density="0" rgba="0.741176 0.901961 0.956863 1" mesh="link1"/>
      <geom type="mesh" rgba="0.741176 0.901961 0.956863 1" mesh="link1"/>
      <body name="link2" pos="0.0005 0.0227 0.0315">
        <inertial pos="0 -0.0187069 0.0525" quat="0.707107 0.707107 0 0" mass="0.0182961" diaginertia="1.62398e-05 1.05133e-05 7.56857e-06"/>
        <joint name="joint2" pos="0 0 0" axis="0 -1 0" range="-3.57 3.57"/>
        <geom type="mesh" contype="0" conaffinity="0" group="1" density="0" rgba="0.741176 0.901961 0.956863 1" mesh="link2"/>
        <geom type="mesh" rgba="0.741176 0.901961 0.956863 1" mesh="link2"/>
        <body name="link3" pos="0 0.001 0.105">
          <inertial pos="-0.00111508 -0.02297 0.0221504" quat="0.795346 0.606035 0.0119194 0.00192163" mass="0.049761" diaginertia="1.97746e-05 1.21915e-05 1.15879e-05"/>
          <joint name="joint3" pos="0 0 0" axis="0 1 0" range="-3.57 3.57"/>
          <geom type="mesh" contype="0" conaffinity="0" group="1" density="0" rgba="0.741176 0.901961 0.956863 1" mesh="link3"/>
          <geom type="mesh" rgba="0.741176 0.901961 0.956863 1" mesh="link3"/>
          <body name="link4" pos="0.0010378 -0.0015 0.0975">
            <inertial pos="-0.0213103 -0.0185844 0.0110816" quat="0.760114 0.649393 0.0212255 -0.00805172" mass="0.0878001" diaginertia="2.46746e-05 1.80257e-05 1.60191e-05"/>
            <joint name="joint4" pos="0 0 0" axis="0 1 0" range="-3.8 3.57"/>
            <geom type="mesh" contype="0" conaffinity="0" group="1" density="0" rgba="0.741176 0.901961 0.956863 1" mesh="link4"/>
            <geom type="mesh" rgba="0.741176 0.901961 0.956863 1" mesh="link4"/>
            <body name="link5" pos="-0.027 -0.0222 0.0432">
              <inertial pos="0.0170982 -0.00181858 0.0338764" quat="0.499359 0.500623 -0.500978 0.499037" mass="0.0430173" diaginertia="1.08203e-05 8.16764e-06 5.73683e-06"/>
              <joint name="joint5" pos="0 0 0" axis="0 0 -1" range="-3.57 3.57"/>
              <geom type="mesh" contype="0" conaffinity="0" group="1" density="0" rgba="0.741176 0.901961 0.956863 1" mesh="link5"/>
              <geom type="mesh" rgba="0.741176 0.901961 0.956863 1" mesh="link5"/>
              <body name="link6" pos="-0.005 -0.0125 0.036042">
                <inertial pos="-0.000194093 -0.00406171 0.00427794" quat="0.928762 0.370677 0 0" mass="0.00295713" diaginertia="3.69052e-07 3.21218e-07 6.02749e-08"/>
                <joint name="joint6" pos="0 0 0" axis="1 0 0" range="-3.8 3.8"/>
                <geom type="mesh" contype="0" conaffinity="0" group="1" density="0" rgba="1 1 1 1" mesh="link6"/>
                <geom type="mesh" rgba="1 1 1 1" mesh="link6"/>
                <body name="link7" pos="-0.007 -0.024099 0.025382">
                  <inertial pos="0.0108164 -0.00658805 0.0193552" quat="0.995458 -0.0952063 0 0" mass="0.011087" diaginertia="2.52356e-06 2.32666e-06 6.49125e-07"/>
                  <joint name="joint7" pos="0 0 0" axis="1 0 0" range="-3.8 3.8"/>
                  <geom type="mesh" contype="0" conaffinity="0" group="1" density="0" rgba="0 0.137255 1 1" mesh="link7"/>
                  <geom type="mesh" rgba="0 0.137255 1 1" mesh="link7"/>
                </body>
              </body>
              <body name="link8" pos="-0.0095 0.0125 0.036042">
                <inertial pos="0.0035 0.00657959 0.00672799" quat="0.925999 -0.377526 0 0" mass="0.00185869" diaginertia="3.62044e-07 3.24019e-07 4.08138e-08"/>
                <joint name="joint8" pos="0 0 0" axis="-1 0 0" range="-0.8 0.8"/>
                <geom type="mesh" contype="0" conaffinity="0" group="1" density="0" rgba="0.74902 0.74902 0.74902 1" mesh="link8"/>
                <geom type="mesh" rgba="0.74902 0.74902 0.74902 1" mesh="link8"/>
                <body name="link9" pos="-0.0025 0.024471 0.025023">
                  <inertial pos="0.0108164 0.00614995 0.019278" quat="0.995459 0.0951946 0 0" mass="0.011087" diaginertia="2.52356e-06 2.32665e-06 6.49127e-07"/>
                  <joint name="joint9" pos="0 0 0" axis="1 0 0" range="-0.8 0.8"/>
                  <geom type="mesh" contype="0" conaffinity="0" group="1" density="0" rgba="1 1 1 1" mesh="link9"/>
                  <geom type="mesh" rgba="1 1 1 1" mesh="link9"/>
                </body>
              </body>
              <body name="link10" pos="-0.008 -0.032703 0.028688">
                <inertial pos="0.0075 -0.0127748 0.0120023" quat="0.928762 0.370677 0 0" mass="0.00108779" diaginertia="1.71923e-07 1.698e-07 3.75425e-09"/>
                <joint name="joint10" pos="0 0 0" axis="1 0 0" range="-0.8 0.8"/>
                <geom type="mesh" contype="0" conaffinity="0" group="1" density="0" rgba="1 1 1 1" mesh="link10"/>
                <geom type="mesh" rgba="1 1 1 1" mesh="link10"/>
              </body>
              <body name="link11" pos="-0.008 0.032703 0.028688">
                <inertial pos="0.0075 0.0129506 0.0118123" quat="0.925999 -0.377526 0 0" mass="0.00108779" diaginertia="1.71923e-07 1.698e-07 3.75425e-09"/>
                <joint name="joint11" pos="0 0 0" axis="-1 0 0" range="-0.8 0.8"/>
                <geom type="mesh" contype="0" conaffinity="0" group="1" density="0" rgba="1 1 1 1" mesh="link11"/>
                <geom type="mesh" rgba="1 1 1 1" mesh="link11"/>
              </body>
            </body>
          </body>
        </body>
      </body>
    </body>
  </worldbody>
</mujoco>
